<robot xmlns:xacro="http://ros.org/wiki/xacro" name="humanoi_robot">
  <xacro:include filename="$(find humanoid_robot_description)/urdf/_d435.urdf.xacro"/>

  <link name="base_link">
    <inertial>
      <origin xyz="0.000106771898555624 -0.00950333311264856 0.421923246207401" rpy="0 0 0"/>
      <mass value="1.09045449262295"/>
      <inertia ixx="0.1329526918414" ixy="4.52001568995455E-06" ixz="-4.72627768389478E-05" iyy="0.132960613916937" iyz="0.00458399908461352" izz="0.00114729742430935"/>
    </inertial>
    <visual>
      <origin xyz="0 0 0" rpy="0 0 0"/>
      <geometry>
        <mesh filename="package://humanoid_robot_description/meshes/base_link.STL"/>
      </geometry>
      <material name="">
        <color rgba="0.792156862745098 0.819607843137255 0.933333333333333 1"/>
      </material>
    </visual>
    <collision>
      <origin xyz="0 0 0" rpy="0 0 0"/>
      <geometry>
        <mesh filename="package://humanoid_robot_description/meshes/base_link.STL"/>
      </geometry>
    </collision>
  </link>

  <link name="left_link">
    <inertial>
      <origin xyz="1.35240152410177E-11 -4.29594135015199E-07 -0.0495805946191804" rpy="0 0 0"/>
      <mass value="1.59252474408208"/>
      <inertia ixx="1.79972735915405E-05" ixy="4.57739569311539E-16" ixz="-4.93968193674911E-13" iyy="1.79972590513083E-05" iyz="1.56909393548931E-08" izz="1.45402322064866E-11"/>
    </inertial>
    <visual>
      <origin xyz="0 0 0" rpy="0 0 0"/>
      <geometry>
        <mesh filename="package://humanoid_robot_description/meshes/left_link.STL"/>
      </geometry>
      <material name="">
        <color rgba="0.792156862745098 0.819607843137255 0.933333333333333 1"/>
      </material>
    </visual>
    <collision>
      <origin xyz="0 0 0" rpy="0 0 0"/>
      <geometry>
        <mesh filename="package://humanoid_robot_description/meshes/left_link.STL"/>
      </geometry>
    </collision>
  </link>

  <joint name="left_joint" type="continuous">
    <origin xyz="0.105499999999999 0 0.159" rpy="1.5707963267949 0.391796412189497 -1.5707963267949"/>
    <parent link="base_link"/>
    <child link="left_link"/>
    <axis xyz="0 0 -1"/>
  </joint>

  <link name="right_link">
    <inertial>
      <origin xyz="1.35241262633201E-11 -4.29594134876421E-07 -0.0495805946191804" rpy="0 0 0"/>
      <mass value="1.59252474408208"/>
      <inertia ixx="1.79972735915405E-05" ixy="4.57743804476276E-16" ixz="-4.9396815848458E-13" iyy="1.79972590513083E-05" iyz="1.5690939354991E-08" izz="1.45402322066618E-11"/>
    </inertial>
    <visual>
      <origin xyz="0 0 0" rpy="0 0 0"/>
      <geometry>
        <mesh filename="package://humanoid_robot_description/meshes/right_link.STL"/>
      </geometry>
      <material name="">
        <color rgba="0.792156862745098 0.819607843137255 0.933333333333333 1"/>
      </material>
    </visual>
    <collision>
      <origin xyz="0 0 0" rpy="0 0 0"/>
      <geometry>
        <mesh filename="package://humanoid_robot_description/meshes/right_link.STL"/>
      </geometry>
    </collision>
  </link>

  <joint name="right_joint" type="continuous">
    <origin xyz="-0.10550000000006 0 0.159000000000006" rpy="1.57079632679489 -0.391796412189497 1.5707963267949"/>
    <parent link="base_link"/>
    <child link="right_link"/>
    <axis xyz="0 0 1"/>
  </joint>

  <sensor_d435 parent="base_link">
    <origin xyz="4.75506188300778E-05 -0.0781614423708992 0.938311218159223" rpy="0 0 -1.57079777883574"/>
  </sensor_d435>

  <!-- 4.75506188300778E-05 -0.0921614423708992 0.950311218159223 1.57079777883573 0 0 -->
  <!-- <joint name="cam_joint" type="fixed"> <origin xyz="4.75506188300778E-05 -0.0921614423708992 0.950311218159223" rpy="1.57079777883573 0 0"/> <parent link="base_link"/> <child link="cam_link"/> <axis xyz="0 0 0"/> </joint> -->

</robot>